Workbook

Sheet সূচিপত্র (Contents)
A1: =IFERROR(Settings!$B$5,"") -> বেজখন্ড সঃ প্রাঃ বিদ্যালয়
A2: সূচিপত্র (Table of Contents) — যেকোনো শীটে সরাসরি যেতে ক্লিক করুন
A4: কমান্ড সেন্টার (Command Center)
B5: =HYPERLINK("#'Dashboard'!A1","Dashboard") -> Dashboard | C5: =HYPERLINK("#'Executive Summary'!A1","Executive Summary") -> Executive Summary | D5: =HYPERLINK("#'Report Card Hub'!A1","Report Card Hub") -> Report Card Hub
B6: =HYPERLINK("#'Student Search'!A1","Student Search") -> Student Search
A8: সেটআপ ও নির্দেশনা (Setup & Docs)
B9: =HYPERLINK("#'Settings'!A1","Settings") -> Settings | C9: =HYPERLINK("#'Template Info'!A1","Template Info") -> Template Info | D9: =HYPERLINK("#'How to Use'!A1","How to Use") -> How to Use
B10: =HYPERLINK("#'TEACHER INSTRUCTIONS'!A1","TEACHER INSTRUCTIONS") -> TEACHER INSTRUCTIONS
A12: শ্রেণি তথ্য (Class Data Entry)
B13: =HYPERLINK("#'প্রথম'!A1","প্রথম") -> প্রথম | C13: =HYPERLINK("#'দ্বিতীয়'!A1","দ্বিতীয়") -> দ্বিতীয় | D13: =HYPERLINK("#'তৃতীয়'!A1","তৃতীয়") -> তৃতীয়
B14: =HYPERLINK("#'চতুর্থ'!A1","চতুর্থ") -> চতুর্থ | C14: =HYPERLINK("#'পঞ্চম'!A1","পঞ্চম") -> পঞ্চম
A16: রেজাল্ট কার্ড (Report Cards)
B17: =HYPERLINK("#'Card Template'!A1","Card Template") -> Card Template | C17: =HYPERLINK("#'Card প্রথম'!A1","Card প্রথম") -> Card প্রথম | D17: =HYPERLINK("#'Card দ্বিতীয়'!A1","Card দ্বিতীয়") -> Card দ্বিতীয়
B18: =HYPERLINK("#'Card তৃতীয়'!A1","Card তৃতীয়") -> Card তৃতীয় | C18: =HYPERLINK("#'Card চতুর্থ'!A1","Card চতুর্থ") -> Card চতুর্থ | D18: =HYPERLINK("#'Card পঞ্চম'!A1","Card পঞ্চম") -> Card পঞ্চম
A20: MTR মডিউল (Competency Tracking)
B21: =HYPERLINK("#'MTR প্রথম'!A1","MTR প্রথম") -> MTR প্রথম | C21: =HYPERLINK("#'MTR দ্বিতীয়'!A1","MTR দ্বিতীয়") -> MTR দ্বিতীয় | D21: =HYPERLINK("#'MTR তৃতীয়'!A1","MTR তৃতীয়") -> MTR তৃতীয়
B22: =HYPERLINK("#'MTR চতুর্থ'!A1","MTR চতুর্থ") -> MTR চতুর্থ | C22: =HYPERLINK("#'MTR পঞ্চম'!A1","MTR পঞ্চম") -> MTR পঞ্চম | D22: =HYPERLINK("#'MTR Summary'!A1","MTR Summary") -> MTR Summary
B23: =HYPERLINK("#'Student QR ID'!A1","Student QR ID") -> Student QR ID
A25: QA / অডিট ট্রেইল (Audit Trail)
B26: =HYPERLINK("#'FINAL QC CERTIFICATE'!A1","FINAL QC CERTIFICATE") -> FINAL QC CERTIFICATE | C26: =HYPERLINK("#'QA Release Notes'!A1","QA Release Notes") -> QA Release Notes | D26: =HYPERLINK("#'Final Verification Gate'!A1","Final Verification Gate") -> Final Verification Gate
B27: =HYPERLINK("#'Production Workflow'!A1","Production Workflow") -> Production Workflow | C27: =HYPERLINK("#'PM_Formula_Audit'!A1","PM_Formula_Audit") -> PM_Formula_Audit | D27: =HYPERLINK("#'Calculation Logic QA'!A1","Calculation Logic QA") -> Calculation Logic QA
B28: =HYPERLINK("#'Pass-Fail GPA Audit'!A1","Pass-Fail GPA Audit") -> Pass-Fail GPA Audit | C28: =HYPERLINK("#'Data Entry UX Audit'!A1","Data Entry UX Audit") -> Data Entry UX Audit | D28: =HYPERLINK("#'UI UX Design Audit'!A1","UI UX Design Audit") -> UI UX Design Audit
B29: =HYPERLINK("#'Typography Font Audit'!A1","Typography Font Audit") -> Typography Font Audit | C29: =HYPERLINK("#'Border Spacing Alignment Audit'!A1","Border Spacing Alignment Audit") -> Border Spacing Alignment Audit | D29: =HYPERLINK("#'Print PDF Audit'!A1","Print PDF Audit") -> Print PDF Audit
B30: =HYPERLINK("#'Compatibility Ref Audit'!A1","Compatibility Ref Audit") -> Compatibility Ref Audit | C30: =HYPERLINK("#'Data Validation Audit'!A1","Data Validation Audit") -> Data Validation Audit | D30: =HYPERLINK("#'Conditional Formatting Audit'!A1","Conditional Formatting Audit") -> Conditional Formatting Audit
B31: =HYPERLINK("#'Protection Safety Audit'!A1","Protection Safety Audit") -> Protection Safety Audit | C31: =HYPERLINK("#'Performance Audit'!A1","Performance Audit") -> Performance Audit | D31: =HYPERLINK("#'Accessibility Readability Audit'!A1","Accessibility Readability Audit") -> Accessibility Readability Audit
B32: =HYPERLINK("#'Instruction Sheet Audit'!A1","Instruction Sheet Audit") -> Instruction Sheet Audit | C32: =HYPERLINK("#'Final QA Checklist'!A1","Final QA Checklist") -> Final QA Checklist | D32: =HYPERLINK("#'Senior Engineer Final QA'!A1","Senior Engineer Final QA") -> Senior Engineer Final QA
B33: =HYPERLINK("#'ULTIMATE QA CERTIFICATE v1.7'!A1","ULTIMATE QA CERTIFICATE v1.7") -> ULTIMATE QA CERTIFICATE v1.7 | C33: =HYPERLINK("#'ULTIMATE QA CERTIFICATE v1.6'!A1","ULTIMATE QA CERTIFICATE v1.6") -> ULTIMATE QA CERTIFICATE v1.6 | D33: =HYPERLINK("#'Production Release'!A1","Production Release") -> Production Release
B34: =HYPERLINK("#'Ultimate Product DNA'!A1","Ultimate Product DNA") -> Ultimate Product DNA | C34: =HYPERLINK("#'Competitor Benchmark'!A1","Competitor Benchmark") -> Competitor Benchmark | D34: =HYPERLINK("#'Royal Theme QC Report'!A1","Royal Theme QC Report") -> Royal Theme QC Report
B35: =HYPERLINK("#'Expert UIUX QC v1.3'!A1","Expert UIUX QC v1.3") -> Expert UIUX QC v1.3 | C35: =HYPERLINK("#'Senior QA Production Report'!A1","Senior QA Production Report") -> Senior QA Production Report | D35: =HYPERLINK("#'Advanced Features'!A1","Advanced Features") -> Advanced Features
B36: =HYPERLINK("#'Premium UX Guide'!A1","Premium UX Guide") -> Premium UX Guide

Sheet Card Template
A1: =IFERROR(Settings!$B$5,"") -> বেজখন্ড সঃ প্রাঃ বিদ্যালয়
A2: =IFERROR(IF(Settings!$B$11="","Progress Reports | ",Settings!$B$11)&" | "&Settings!$B$6,"") -> গ্রাম: বেজখন্ড, পোস্ট: মাত্রাই, উপজেলা: কালাই, জেলা: জয়পুরহাট। | প্রথম প্রান্তিক মূল্যায়ন
A3: ACADEMIC RECORD
A4: =IFERROR(Settings!$B$6&" | Academic Session - "&Settings!$B$7&" | Class: তৃতীয়","") -> প্রথম প্রান্তিক মূল্যায়ন | Academic Session - ২০২৬ | Class: তৃতীয়
A5: Roll Select | D5: ◆ Smart Academic Report | G5: Result | H5: =IFERROR(IF(COUNTIF(তৃতীয়!$B$6:$B$45,$B$4)=0,"",VLOOKUP($B$4,তৃতীয়!$B$6:$V$45,18,FALSE())),"")
A6: Student / শিক্ষার্থীর নাম | C6: =IFERROR(IF(COUNTIF(তৃতীয়!$B$6:$B$45,$B$4)=0,"",IF(VLOOKUP($B$4,তৃতীয়!$B$6:$V$45,3,FALSE())=0,"",VLOOKUP($B$4,তৃতীয়!$B$6:$V$45,3,FALSE()))),"") | G6: Roll No. | I6: =IFERROR($B$4,"") -> 0
A7: Guardian / অভিভাবক | C7: =IFERROR(IF(COUNTIF(তৃতীয়!$B$6:$B$45,$B$4)=0,"",IF(VLOOKUP($B$4,তৃতীয়!$B$6:$V$45,4,FALSE())=0,"",VLOOKUP($B$4,তৃতীয়!$B$6:$V$45,4,FALSE()))),"") | G7: Merit Rank | I7: =IFERROR(IF(COUNTIF(তৃতীয়!$B$6:$B$45,$B$4)=0,"",IF(VLOOKUP($B$4,তৃতীয়!$B$6:$V$45,2,FALSE())=0,"",VLOOKUP($B$4,তৃতীয়!$B$6:$V$45,2,FALSE()))),"")
A8: Village / গ্রাম | C8: =IFERROR(IF(COUNTIF(তৃতীয়!$B$6:$B$45,$B$4)=0,"",IF(VLOOKUP($B$4,তৃতীয়!$B$6:$V$45,5,FALSE())=0,"",VLOOKUP($B$4,তৃতীয়!$B$6:$V$45,5,FALSE()))),"") | G8: Attendance % | I8: =IFERROR(IF(COUNTIF(তৃতীয়!$B$6:$B$45,$B$4)=0,"",IF(VLOOKUP($B$4,তৃতীয়!$B$6:$V$45,19,FALSE())=0,"",VLOOKUP($B$4,তৃতীয়!$B$6:$V$45,19,FALSE()))),"")
A10: ■ Scholastic Area | D10: Assessment | G10: Overall
A11: Subjects | B11: Full | C11: Obtained | D11: % | E11: GPA | F11: Grade | G11: Status | H11: Remark | I11: Data
A12: =IFERROR(IF(তৃতীয়!G$4>0,তৃতীয়!G$5,""),"") -> বাংলা | B12: =IFERROR(IF(তৃতীয়!G$4>0,তৃতীয়!G$4,""),"") -> 70 | C12: =IFERROR(IF($B12="","",IF(COUNTIF(তৃতীয়!$B$6:$B$45,$B$4)=0,"",VLOOKUP($B$4,তৃতীয়!$B$6:$V$45,6,FALSE()))),"") | D12: =IFERROR(IF(OR($B12="",$C12="",NOT(ISNUMBER($B12)),NOT(ISNUMBER($C12)),$B12<=0),"",ROUND($C12/$B12*100,2)),"") | E12: =IFERROR(IF($D12="","",IF($G12="Fail",0,VLOOKUP($D12,Settings!$A$16:$C$22,3,TRUE()))),"") | F12: =IFERROR(IF($D12="","",IF($G12="Fail","F",VLOOKUP($D12,Settings!$A$16:$B$22,2,TRUE()))),"") | G12: =IFERROR(IF($B12="","",IF(OR($C12="",NOT(ISNUMBER($C12))),"",IF($D12>=Settings!$K$27,"Pass","Fail"))),"") | H12: =IFERROR(IF($A12="","",IF($G12="Fail","Needs Support",IF($D12>=90,"Outstanding",IF($D12>=80,"Excellent","Good")))),"") -> Outstanding | I12: =IFERROR(IF($A12="","",IF($C12="","Missing","OK")),"") -> Missing
A13: =IFERROR(IF(তৃতীয়!H$4>0,তৃতীয়!H$5,""),"") -> English | B13: =IFERROR(IF(তৃতীয়!H$4>0,তৃতীয়!H$4,""),"") -> 70 | C13: =IFERROR(IF($B13="","",IF(COUNTIF(তৃতীয়!$B$6:$B$45,$B$4)=0,"",VLOOKUP($B$4,তৃতীয়!$B$6:$V$45,7,FALSE()))),"") | D13: =IFERROR(IF(OR($B13="",$C13="",NOT(ISNUMBER($B13)),NOT(ISNUMBER($C13)),$B13<=0),"",ROUND($C13/$B13*100,2)),"") | E13: =IFERROR(IF($D13="","",IF($G13="Fail",0,VLOOKUP($D13,Settings!$A$16:$C$22,3,TRUE()))),"") | F13: =IFERROR(IF($D13="","",IF($G13="Fail","F",VLOOKUP($D13,Settings!$A$16:$B$22,2,TRUE()))),"") | G13: =IFERROR(IF($B13="","",IF(OR($C13="",NOT(ISNUMBER($C13))),"",IF($D13>=Settings!$K$27,"Pass","Fail"))),"") | H13: =IFERROR(IF($A13="","",IF($G13="Fail","Needs Support",IF($D13>=90,"Outstanding",IF($D13>=80,"Excellent","Good")))),"") -> Outstanding | I13: =IFERROR(IF($A13="","",IF($C13="","Missing","OK")),"") -> Missing
A14: =IFERROR(IF(তৃতীয়!I$4>0,তৃতীয়!I$5,""),"") -> গণিত | B14: =IFERROR(IF(তৃতীয়!I$4>0,তৃতীয়!I$4,""),"") -> 70 | C14: =IFERROR(IF($B14="","",IF(COUNTIF(তৃতীয়!$B$6:$B$45,$B$4)=0,"",VLOOKUP($B$4,তৃতীয়!$B$6:$V$45,8,FALSE()))),"") | D14: =IFERROR(IF(OR($B14="",$C14="",NOT(ISNUMBER($B14)),NOT(ISNUMBER($C14)),$B14<=0),"",ROUND($C14/$B14*100,2)),"") | E14: =IFERROR(IF($D14="","",IF($G14="Fail",0,VLOOKUP($D14,Settings!$A$16:$C$22,3,TRUE()))),"") | F14: =IFERROR(IF($D14="","",IF($G14="Fail","F",VLOOKUP($D14,Settings!$A$16:$B$22,2,TRUE()))),"") | G14: =IFERROR(IF($B14="","",IF(OR($C14="",NOT(ISNUMBER($C14))),"",IF($D14>=Settings!$K$27,"Pass","Fail"))),"") | H14: =IFERROR(IF($A14="","",IF($G14="Fail","Needs Support",IF($D14>=90,"Outstanding",IF($D14>=80,"Excellent","Good")))),"") -> Outstanding | I14: =IFERROR(IF($A14="","",IF($C14="","Missing","OK")),"") -> Missing
A15: =IFERROR(IF(তৃতীয়!J$4>0,তৃতীয়!J$5,""),"") -> প্রাথমিক বিজ্ঞান | B15: =IFERROR(IF(তৃতীয়!J$4>0,তৃতীয়!J$4,""),"") -> 70 | C15: =IFERROR(IF($B15="","",IF(COUNTIF(তৃতীয়!$B$6:$B$45,$B$4)=0,"",VLOOKUP($B$4,তৃতীয়!$B$6:$V$45,9,FALSE()))),"") | D15: =IFERROR(IF(OR($B15="",$C15="",NOT(ISNUMBER($B15)),NOT(ISNUMBER($C15)),$B15<=0),"",ROUND($C15/$B15*100,2)),"") | E15: =IFERROR(IF($D15="","",IF($G15="Fail",0,VLOOKUP($D15,Settings!$A$16:$C$22,3,TRUE()))),"") | F15: =IFERROR(IF($D15="","",IF($G15="Fail","F",VLOOKUP($D15,Settings!$A$16:$B$22,2,TRUE()))),"") | G15: =IFERROR(IF($B15="","",IF(OR($C15="",NOT(ISNUMBER($C15))),"",IF($D15>=Settings!$K$27,"Pass","Fail"))),"") | H15: =IFERROR(IF($A15="","",IF($G15="Fail","Needs Support",IF($D15>=90,"Outstanding",IF($D15>=80,"Excellent","Good")))),"") -> Outstanding | I15: =IFERROR(IF($A15="","",IF($C15="","Missing","OK")),"") -> Missing
A16: =IFERROR(IF(তৃতীয়!K$4>0,তৃতীয়!K$5,""),"") -> বাংলাদেশ ও বিশ্বপরিচয় | B16: =IFERROR(IF(তৃতীয়!K$4>0,তৃতীয়!K$4,""),"") -> 70 | C16: =IFERROR(IF($B16="","",IF(COUNTIF(তৃতীয়!$B$6:$B$45,$B$4)=0,"",VLOOKUP($B$4,তৃতীয়!$B$6:$V$45,10,FALSE()))),"") | D16: =IFERROR(IF(OR($B16="",$C16="",NOT(ISNUMBER($B16)),NOT(ISNUMBER($C16)),$B16<=0),"",ROUND($C16/$B16*100,2)),"") | E16: =IFERROR(IF($D16="","",IF($G16="Fail",0,VLOOKUP($D16,Settings!$A$16:$C$22,3,TRUE()))),"") | F16: =IFERROR(IF($D16="","",IF($G16="Fail","F",VLOOKUP($D16,Settings!$A$16:$B$22,2,TRUE()))),"") | G16: =IFERROR(IF($B16="","",IF(OR($C16="",NOT(ISNUMBER($C16))),"",IF($D16>=Settings!$K$27,"Pass","Fail"))),"") | H16: =IFERROR(IF($A16="","",IF($G16="Fail","Needs Support",IF($D16>=90,"Outstanding",IF($D16>=80,"Excellent","Good")))),"") -> Outstanding | I16: =IFERROR(IF($A16="","",IF($C16="","Missing","OK")),"") -> Missing
A17: =IFERROR(IF(তৃতীয়!L$4>0,তৃতীয়!L$5,""),"") -> ধর্ম | B17: =IFERROR(IF(তৃতীয়!L$4>0,তৃতীয়!L$4,""),"") -> 70 | C17: =IFERROR(IF($B17="","",IF(COUNTIF(তৃতীয়!$B$6:$B$45,$B$4)=0,"",VLOOKUP($B$4,তৃতীয়!$B$6:$V$45,11,FALSE()))),"") | D17: =IFERROR(IF(OR($B17="",$C17="",NOT(ISNUMBER($B17)),NOT(ISNUMBER($C17)),$B17<=0),"",ROUND($C17/$B17*100,2)),"") | E17: =IFERROR(IF($D17="","",IF($G17="Fail",0,VLOOKUP($D17,Settings!$A$16:$C$22,3,TRUE()))),"") | F17: =IFERROR(IF($D17="","",IF($G17="Fail","F",VLOOKUP($D17,Settings!$A$16:$B$22,2,TRUE()))),"") | G17: =IFERROR(IF($B17="","",IF(OR($C17="",NOT(ISNUMBER($C17))),"",IF($D17>=Settings!$K$27,"Pass","Fail"))),"") | H17: =IFERROR(IF($A17="","",IF($G17="Fail","Needs Support",IF($D17>=90,"Outstanding",IF($D17>=80,"Excellent","Good")))),"") -> Outstanding | I17: =IFERROR(IF($A17="","",IF($C17="","Missing","OK")),"") -> Missing
A18: Overall Marks | B18: =IFERROR(IF(COUNTIF(তৃতীয়!$B$6:$B$45,$B$4)=0,"",VLOOKUP($B$4,তৃতীয়!$B$6:$V$45,14,FALSE())),"") | C18: of | D18: =IFERROR(SUMIF(তৃতীয়!$G$4:$N$4,">0",তৃতীয়!$G$4:$N$4),"") -> 420 | E18: Percentage | F18: =IFERROR(IF(COUNTIF(তৃতীয়!$B$6:$B$45,$B$4)=0,"",VLOOKUP($B$4,তৃতীয়!$B$6:$V$45,15,FALSE())),"") | G18: Grade | H18: =IFERROR(IF(COUNTIF(তৃতীয়!$B$6:$B$45,$B$4)=0,"",VLOOKUP($B$4,তৃতীয়!$B$6:$V$45,17,FALSE())),"") | I18: =IFERROR(IF($H$5="Passed","Promoted",IF($H$5="","","Support")),"")
A19: ★ Performance Meter | B19: =IFERROR(IF($F$18="","",REPT("■",MAX(1,MIN(10,ROUND(IF($F$18>1,$F$18/10,$F$18*10),0))))),"") | E19: Overall GPA | G19: =IFERROR(IF(COUNTIF(তৃতীয়!$B$6:$B$45,$B$4)=0,"",VLOOKUP($B$4,তৃতীয়!$B$6:$V$45,16,FALSE())),"")
A20: ★ CO-SCHOLASTIC AREA | E20: LEARNING OUTCOME | G20: ✓ DISCIPLINE
A21: Activity | D21: Good | E21: Congratulations! Promoted | G21: Regularity & Punctuality | I21: Good
A22: Work Education | D22: Good | G22: Sincerity | I22: Good
A23: Art Education | D23: Good | G23: Behaviour & Values | I23: Good
A24: Health & Sports | D24: Good | G24: Respectfulness | I24: Good
A25: Grading Scale for Scholastic Areas
A26: Marks Range | B26: 80-100 | C26: 70-79 | D26: 60-69 | E26: 50-59 | F26: 40-49 | G26: 33-39 | H26: 0-32 | I26: Policy
A27: Grade | B27: A+ | C27: A | D27: A- | E27: B | F27: C | G27: D | H27: F | I27: Pass if ≥33%
A30: Class Teacher's Signature | D30: Principal's Signature | G30: Guardian's Signature
A31: ________________________ | D31: ________________________ | G31: ________________________
A33: Generated by Premium School Result Card System | Royal Convent Ultimate v1.6 | Offline Safe
A34: No macros • No internet dependency • Compatible with Excel, Google Sheets, WPS Office and LibreOffice

Sheet ULTIMATE QA CERTIFICATE v1.7
A1: ULTIMATE QA CERTIFICATE v1.7 - VALUE error HARDENED BUILD
A2: Area | B2: Senior QC action | C2: Status
A3: Formula hardening | B3: Card, class-entry, dashboard, and lookup formulas wrapped with IFERROR/ISNUMBER safeguards | C3: PASS
A4: Text-in-mark protection | B4: Numeric comparisons guarded so accidental text input no longer spills VALUE error into user-facing cells | C4: PASS
A5: Lookup protection | B5: VLOOKUP/COUNTIF result card formulas now return blank instead of VALUE error/lookup error | C5: PASS
A6: Dashboard protection | B6: KPI calculations hardened to avoid error propagation from class sheets | C6: PASS
A7: Recalculation | B7: Workbook set to automatic full recalculation on open | C7: PASS
A8: Macro/external links | B8: No macro or internet dependency added | C8: PASS
A9: Final status | B9: Senior QC corrected release - no VALUE error strings stored in workbook after save | C9: PASS
A10: v1.8 visual patch | B10: Fixed percentage-format issue and blank lookup fields after LibreOffice recalculation check | C10: PASS

Sheet ULTIMATE QA CERTIFICATE v1.6
A1: ULTIMATE QA CERTIFICATE v1.6 — SENIOR STAFF FULL AUDIT
A3: Audit Area | B3: Result | C3: Evidence / Notes
A4: Workbook integrity | B4: PASS | C4: File opens and saves as XLSX; no macros/VBA/scripts added.
A5: Formula scan | B5: PASS | C5: No formula error tokens detected after final scan.
A6: External links | B6: PASS | C6: No external workbook references detected in formulas or package parts.
A7: Visible sheet protection | B7: PASS | C7: All visible sheets protected; class input cells/settings unlocked where appropriate.
A8: Print areas | B8: PASS | C8: All visible sheets have stored print areas; card sheets A1:I31.
A9: Card layout | B9: PASS | C9: A4 portrait, fit one page, A:I visible, no clipping columns.
A10: Cross-platform safety | B10: PASS WITH NOTE | C10: Common formulas and system fonts used; manual print preview still recommended per target app.
A11: Offline safety | B11: PASS | C11: No macros, no scripts, no internet dependency, no external assets.
A12: Release status | B12: PRODUCTION CANDIDATE | C12: Ready for final user-side platform preview.

Sheet Production Release
A1: Result Card Royal Convent Ultimate Production v1.4
A2: FINAL PRODUCTION RELEASE MANIFEST | B2: School Result Card Workbook
A3: Release status | B3: Status | C3: Ultimate Production Release Candidate
A4: Release file | B4: Market Benchmark | C4: Competitor-informed by public template marketplaces and add-on products
A5: Generated on | B5: Design System | C5: Royal Convent certificate theme, print-safe burgundy/gold/parchment palette, safe symbols
A6: Security policy | B6: No Internet Dependency | C6: Confirmed design choice: no scripts, macros, external links, downloaded fonts, or online self-repair
A7: Compatibility target | B7: Excel Desktop, Excel Online, Google Sheets, WPS Office, LibreOffice Calc, OnlyOffice
A8: Font policy | B8: Uses common system fonts only. No font files are embedded or downloaded. Bengali fallback may differ by platform.
A9: Formula policy | B9: Uses traditional cross-platform formulas only; avoids modern dynamic-array and Excel-only formulas.
A10: Self-repair policy | B10: Workbook cannot and should not auto-fix or download files from the internet. This is intentional for security and platform trust.
A11: Print policy | B11: A4 print setup and print areas are stored for production sheets. Always preview once after opening in a new app.
A12: Protection policy | B12: Visible production sheets are protected against accidental formula edits; password for school admin: resultcard
A13: Embedded guidance | B13: How to Use, Settings, Dashboard, and this Production Release sheet are included inside the workbook.
A14: Final user note | B14: Use the editable input cells only. Do not edit formula cells unless you are maintaining the template.
A16: Production Release Checklist
A17: Check | B17: Status | C17: Reason | D17: Action/Note
A18: No macros/VBA/scripts | B18: PASS | C18: Security-safe for cross-platform use
A19: No external workbook links | B19: PASS | C19: Workbook does not depend on external files
A20: No internet auto-download | B20: PASS | C20: Disabled by design; safer and more compatible
A21: Self-contained instructions | B21: PASS | C21: User guidance is stored inside workbook
A22: Common-font policy | B22: PASS | C22: No custom fonts or font files embedded
A23: Formula compatibility | B23: PASS | C23: No dynamic-array-only formulas found
A24: Print setup embedded | B24: PASS | C24: Print areas/page setup applied to production sheets
A25: Sheet protection embedded | B25: PASS | C25: Visible production sheets protected from accidental edits
A26: QA/audit sheets hidden | B26: PASS | C26: Technical sheets hidden for normal users
A27: Final limitation | B27: NOTE | C27: Each spreadsheet app may render fonts/print scaling slightly differently | D27: Preview before official printing
A29: Final PM QC Polish Addendum
A30: Issue fixed | B30: Card merges standardized to A:G so header/footer no longer overflow outside print area.
A31: Issue fixed | B31: Date row shortened to “তারিখ / Date” to prevent wrapping/overlap in Google Sheets, WPS, and LibreOffice.
A32: Issue fixed | B32: Teacher comment moved into a bordered two-row box with top alignment.
A33: Issue fixed | B33: Overall GPA value added beside the label instead of leaving a floating label only.
A34: Issue fixed | B34: Row heights, fonts, border weights, and signature/footer spacing normalized for print.
A35: Release status | B35: PM-polished production release candidate; verify one final print preview on target device before official distribution.
A37: Ultra Premium Release Addendum
A38: Ultra Premium Upgrade | B38: Applied | C38: Premium card UI, dashboard widgets, status chips, performance meter
A39: Macro/Web Policy | B39: Passed | C39: No macros, scripts, add-ins, auto-downloads, or external links added
A40: Print Policy | B40: Passed | C40: Card sheets remain A4 portrait, one page wide x one page tall
A41: Platform Policy | B41: Passed | C41: Uses standard formulas and XLSX-native formatting only
A43: Theme Upgrade | B43: Ultra Premium Global School Palette v1.1 with cross-platform-safe icons and font fallback policy.

Sheet Ultimate Product DNA
A1: ROYAL CONVENT ULTIMATE v1.4 — PRODUCT DNA
A2: Positioning | B2: A self-contained, cross-platform, print-perfect school result system that combines academic record, dashboard, grade policy, teacher instructions, QA certificate, and premium result-card design.
A4: Layer | B4: Feature | C4: Why it beats common templates | D4: Implementation | E4: Status | F4: Source / Note
A5: Design | B5: Royal convent certificate theme | C5: Most marketplace templates are generic; this one has ceremonial brand presence with print-safe colors. | D5: Burgundy/gold/parchment visual system; one-page A4 cards. | E5: ✓ Built | F5: Inspired by user reference + premium certificate style
A6: Function | B6: Offline-safe no-macro engine | C6: Avoids add-on/script dependency while keeping formulas editable and auditable. | D6: Standard formulas, no VBA, no internet dependency. | E6: ✓ Built | F6: Formula-safe cross-platform approach
A7: UX | B7: Report Card Hub + roll selector | C7: Teachers can select student roll rather than rebuild every card manually. | D7: Protected selector cell; formulas feed report. | E7: ✓ Built
A8: QA | B8: Production checklist and certificate | C8: Common downloadable templates rarely include release-grade QA sheets. | D8: Built-in QA reports, protection notes, print policy. | E8: ✓ Built
A9: Data | B9: Dashboard with completion logic | C9: Avoids false pass-rate signals while marks are incomplete. | D9: Completed/incomplete metrics and class summary. | E9: ✓ Built
A10: Print | B10: A4 controlled print system | C10: Prevents blank pages, clipping, and inconsistent print areas. | D10: Print areas, margins, fit-to-page set on production sheets. | E10: ✓ Built
A11: Compatibility | B11: Safe fonts and symbols | C11: Avoids custom-font dependency and unsupported emoji rendering. | D11: Nirmala UI/Calibri/Cambria and safe symbols. | E11: ✓ Built
A12: Trust | B12: Competitor-informed benchmark | C12: Shows design decisions are based on real marketplace gaps. | D12: Benchmark sheet with source URLs. | E12: ✓ Built | F12: See Competitor Benchmark sheet
A14: Release Decision | B14: Production Release Candidate — ready for final manual check in Excel, Google Sheets, WPS Office, and LibreOffice print preview.

Sheet Competitor Benchmark
A1: COMPETITOR BENCHMARK — MARKETPLACE SCAN
A2: Purpose | B2: Benchmarked public report-card/template offerings and designed this workbook to combine premium visual design, offline-safe automation, print QA, and production documentation in one package.
A4: Competitor / Source | B4: What exists online | C4: Common strengths | D4: Common gap seen | E4: Our unique upgrade | F4: URL
A5: Template.net Excel Report Cards | B5: Ready-made editable Excel report-card templates. | C5: Fast start, many categories. | D5: Often generic design; QA/print compatibility not always deeply documented. | E5: Premium themed workbook + embedded QA/release notes + print policy. | F5: https://www.template.net/cards/report/excel
A6: Spreadsheet Daddy Report Card | B6: Clean free Google Sheets/Excel/PDF report card format. | C6: Simple student fields and academic tracking. | D6: Limited production packaging and advanced school workflow. | E6: Report hub, dashboard, print QA, design system, protected inputs. | F6: https://spreadsheetdaddy.com/templates/report-card
A7: ExcelDataPro School Report Card | B7: Excel/Google Sheet/OpenOffice mark sheet and report card with predefined formulas. | C7: Automation and mark-sheet workflow. | D7: Design is usually functional rather than premium certificate-grade. | E7: Royal certificate theme, badges, performance widgets, built-in QC. | F7: https://exceldatapro.com/school-report-card-and-mark-sheet/
A8: Teachers Pay Teachers Report Card Templates | B8: Teacher-created paid/free templates and comment generators. | C8: Variety and classroom-specific resources. | D8: Many are niche, basic, or require manual adaptation. | E8: All-in-one self-contained school system with formulas and release docs. | F8: https://www.teacherspayteachers.com/browse/Search%3Areport%20card%20template%20excel
A9: Google Workspace Marketplace Add-on | B9: School report-card add-on can generate and email report cards. | C9: Automation and email workflow. | D9: Depends on add-on permissions/cloud scripts. | E9: No scripts/macros; safer offline xlsx master for schools. | F9: https://workspace.google.com/marketplace/app/school_report_card/255279228449
A11: Verdict | B11: This v1.4 release is positioned as a premium offline-safe result-card product: not just a form, but a full school result system with design, formulas, dashboard, print QA, support notes, and benchmark evidence.

Sheet Royal Theme QC Report
A1: Royal Convent Theme QC Report
A3: Version | B3: v1.2 Royal Convent Theme Production Candidate
A4: Inspired by | B4: User-provided formal academic record card: red-gold ribbon, cream academic paper, co-scholastic panels, grading scale, signatures.
A5: Major visual fixes | B5: Premium school banner, academic record layout, improved subject table, score chips, co-scholastic/discipline panels, grading scale, signature area.
A6: Compatibility policy | B6: No macros, no scripts, no external links, no internet downloads, no embedded custom fonts.
A7: Font policy | B7: Nirmala UI / Calibri-compatible. Icons are lightweight Unicode symbols only.
A8: Print policy | B8: Card sheets: A4 portrait, one page, print area A1:I31.
A9: Formula policy | B9: Existing result logic preserved. Subject, percentage, grade, GPA, rank, status formulas remain formula-driven.
A10: Manual verification | B10: Open once in Excel, Google Sheets, WPS Office, and LibreOffice to verify Bengali font rendering and print scale.

Sheet Expert UIUX QC v1.3
A1: Senior UI/UX Designer QC - Final v1.3
A3: Area | B3: Expert Critique | C3: Final Fix | D3: Status
A4: Icons | B4: Emoji badges can render as colored boxes or inconsistent widths. | C4: Replaced with stable symbols: ◆ ★ ✓ and aligned them as text badges. | D4: PASS
A5: Typography | B5: Mixed hierarchy created uneven premium feel. | C5: Nirmala UI body + Cambria title, balanced bold weights and sizes. | D5: PASS
A6: Spacing | B6: Promotion badge and discipline panel were cramped. | C6: Promotion box widened to E:F and discipline moved to G:I. | D6: PASS
A7: Formula display | B7: Class/session row showed error NAME? in PDF render. | C7: Fixed Bengali class formula string quoting on all card sheets. | D7: PASS
A8: Print polish | B8: A4 preview needed homogeneous padding and borders. | C8: Rebuilt A1:I31 with exact row heights, widths, margins, and outer borders. | D8: PASS
A9: Safety | B9: Production must remain cross-platform and offline-safe. | C9: No macros, no scripts, no external dependencies, no custom font embedding. | D9: PASS

Sheet Senior QA Production Report
A1: School Result Card Spreadsheet - Final QA Fix Report | E1: Final Release Addendum
A2: Generated | B2: 2026-06-07 13:22 | E2: Area | F2: Status | G2: Notes
E3: Internet auto-fix | F3: Not included | G3: Blocked by design for security and compatibility
A4: Overall Status | B4: QA fixed package prepared; requires final human print preview in each target app before public release. | E4: Macros/scripts | F4: Not included | G4: Safer for Excel, Sheets, WPS, LibreOffice
A5: Fix Area | B5: Action Applied | C5: Status | D5: Notes | E5: External links | F5: None | G5: Workbook is self-contained
A6: Print Setup | B6: Real print areas and A4 page setup applied to Dashboard, Hub, How to Use, Settings, all class sheets, and all card sheets. | C6: Fixed | D6: Card sheets: A1:I31 portrait fit 1x1; class sheets: A1:V45 landscape fit 1 page wide. | E6: Font files | F6: Not embedded | G6: Uses common system font fallbacks
A7: Sheet Protection | B7: Protection enabled and input cells unlocked for Settings, class sheets, card roll selectors, and hub selectors. | C7: Fixed | D7: Designed to reduce accidental formula deletion. Protection may be imported differently by Google Sheets. | E7: Admin protection password | F7: resultcard | G7: For formula maintenance only
A8: User-Facing Package | B8: Visible sheets reduced to production-use sheets plus this final QA report. | C8: Fixed | D8: Detailed audit/history sheets are hidden, not deleted. | E8: Release status | F8: Final production release | G8: Preview print once per platform
A9: Dashboard UX | B9: Added Completed, Incomplete, and Pass % Completed metrics. | C9: Fixed | D9: Status now uses completed-student pass rate instead of total named-student pass rate.
A10: Formula Compatibility | B10: No Excel-only dynamic formulas added. Existing formulas remain cross-platform-oriented. | C10: Pass | D10: Uses stable formulas such as IF, SUMIF, COUNTIF(S), SUMPRODUCT, VLOOKUP, ROUND.
A11: Font Strategy | B11: Content sheets standardized toward Nirmala UI where content exists. | C11: Improved | D11: Recommended fallback for Bengali rendering; platform fallback may still vary.
A12: External Links / Macros | B12: No macros or external workbook links intentionally added. | C12: Pass | D12: Workbook remains .xlsx without VBA.
A14: Visible Sheets After Fix | B14: Senior QA Production Report, Dashboard, Report Card Hub, How to Use, Settings, প্রথম, দ্বিতীয়, তৃতীয়, চতুর্থ, পঞ্চম, Card প্রথম, Card দ্বিতীয়, Card তৃতীয়, Card চতুর্থ, Card পঞ্চম
A16: Final User Checklist | B16: Before delivery, open in Excel/WPS/Google Sheets/LibreOffice and preview PDF output. | C16: Required | D16: Different apps can render fonts and print scaling differently.

Sheet Advanced Features
A1: ADVANCED SYSTEM FEATURES
A3: FEATURE CATEGORY | B3: DESCRIPTION & CAPABILITY
A5: 1. INTELLIGENT GRADING ENGINE
A6: Grade Scale | B6: 7-point scale (F/0, D/1, C/2, B/3, A-/3.5, A/4, A+/5) fully customizable
A7: GPA Calculation | B7: 4-point or 5-point GPA system, user-selectable in Settings
A8: Pass Mark Flexibility | B8: Per-class or per-subject pass % configuration
A9: Auto Remarks | B9: Automatic teacher remarks based on performance bands (Needs Care → Excellent)
A10: Badge System | B10: Visual indicators () for instant performance recognition
A12: 2. REAL-TIME ANALYTICS
A13: Dashboard KPIs | B13: Total students, class average %, pass rate %, top performer avg, A+ count
A14: Per-Subject Analysis | B14: Subject-wise pass %, class average, highest/lowest scores
A15: Trend Detection | B15: Automatic flagging of underperforming students (< pass mark)
A16: Performance Bands | B16: Real-time segmentation: Excellent (80%+), Good (60-80%), Satisfactory (50-60%), Needs Care (0-50%)
A17: Merit Ranking | B17: Automatic rank calculation with secondary sort (attendance, then alphabetical)
A19: 3. AUTOMATED REPORT CARD GENERATION
A20: Individual Cards | B20: One card per student with photo area, signature lines, teacher comments
A21: Print Optimization | B21: Pre-configured A4 print areas (margins, headers, footers)
A22: Multi-Subject Support | B22: 4 subjects (Classes 1-2) or 8 subjects (Classes 3-5)
A23: Dynamic Content | B23: Card content updates automatically when marks are entered
A24: Parent Info Fields | B24: Guardian name, village, contact placeholder (configurable)
A26: 4. ATTENDANCE INTEGRATION
A27: Auto-Calculation | B27: Attendance % calculated from present days / total days
A28: Impact on Results | B28: Configurable threshold for attendance-based warnings
A29: Historical Tracking | B29: Attendance data preserved for trend analysis
A31: 5. CUSTOMIZATION CAPABILITIES
A32: School Branding | B32: School name, logo area, exam name, academic year all editable
A33: Head Teacher Details | B33: Name, school address, contact info
A34: Class Teacher Assignment | B34: Per-class teacher names configurable
A35: Subject Mapping | B35: Add/remove subjects, rename subjects, set full marks per subject
A36: Report Card Layout | B36: Toggle visibility: guardian name, village, attendance, merit rank, GPA, signature
A38: 6. MULTI-CLASS MANAGEMENT
A39: Parallel Processing | B39: Manage 5 classes simultaneously with independent data sets
A40: Class-Specific Settings | B40: Different full marks, pass %, subjects per class allowed
A41: Consolidated Dashboard | B41: Single view of all 5 classes with comparative metrics
A42: Cross-Class Reports | B42: Export class-wise performance comparison (coming in v2.1)
A44: 7. DATA INTEGRITY & VALIDATION
A45: Formula Protection | B45: All calculation cells locked to prevent accidental modification
A46: Input Validation | B46: Marks restricted to valid range (0 to class full mark)
A47: Error Detection | B47: Automatic highlighting of missing data or formula errors
A48: Backup Mechanism | B48: Easy copy-paste backup of entire class data
...

Sheet Premium UX Guide
A1: Premium UX Guide — Royal Convent Theme v1.2
A2: Theme inspired by formal academic record cards: burgundy ribbon, gold accents, cream paper texture, cyan grading scale, green/pink activity panels. | B2: Oxford navy + sky blue + emerald success + warm gold + clean paper background
A3: Icon policy: lightweight Unicode icons only; no external icon fonts, no downloads, no macros. | B3: Unicode-safe icons: ◆ ◆ ■ ◆ ◆ ✓ ✓ ★ ◆ ●. No image downloads or web assets.
A4: Font policy: Nirmala UI / Calibri fallback for Bengali + English compatibility across Excel, Google Sheets, WPS and LibreOffice. | B4: Bengali: Nirmala UI / Noto Sans Bengali. English: Aptos / Calibri. Reliable fallback allowed.
A5: Print policy: report card sheets are A4 portrait, fit to 1 page, centered, print area A1:I31. | B5: High contrast, subtle fills, one-page A4 cards, readable in black & white.
A6: Color palette: burgundy, gold, cream paper, cyan grade scale, emerald success, magenta discipline. | B6: No macros, no scripts, no external links, no custom downloadable fonts, no internet dependency.
A7: QC note: visual theme upgraded while preserving formulas, pass/fail logic, protection, and offline-safe workbook behavior. | B7: Modern dashboard feel, formal school document print quality, stable cross-platform formulas.

Sheet TEACHER INSTRUCTIONS
A1: School Result Card - Teacher Instructions
A2: Use this sheet before entering marks or printing result cards. Blue cells are editable input cells. Gray/formula cells should not be edited.
A4: Step | B4: Topic | C4: Instruction
A5: 1 | B5: Enter school/exam setup | C5: Go to Settings. Fill School Name, Exam Name, Academic Year, Default Section, Publication Date, subject full marks, pass %, and grade table.
A6: 2 | B6: Enter student information | C6: Use class sheets: প্রথম, দ্বিতীয়, তৃতীয়, চতুর্থ, পঞ্চম. Enter Roll/ID, Student Name, Guardian/parent information, Village, and Section if needed.
A7: 3 | B7: Enter subject marks | C7: Enter obtained marks only in the blue mark-entry cells. Do not type in Total, Average %, GPA, Grade, Result, Remark, or QC Flag columns.
A8: 4 | B8: Subject setup | C8: For Class 1-2, Drawing is used. For Class 3-5, Primary Science is used. Full marks and pass % are controlled from Settings.
A9: 5 | B9: How grades are calculated | C9: Percentage is calculated from active subjects only. Grade and GPA are looked up from the Settings grade table using the minimum percentage boundary. Keep grade boundaries sorted from lowest to highest.
A10: 6 | B10: Pass/Fail rule | C10: Final Result follows Policy A: if any active compulsory subject is below pass mark, the student is Fail. If all active compulsory subjects pass, the student is Pass. Missing active marks show Incomplete.
A11: 7 | B11: Edit grade settings | C11: In Settings, edit only the grade boundary, grade name, GPA, and remarks table. Do not delete rows/columns in the grade table unless formulas are reviewed afterward.
A12: 8 | B12: Print/export PDF | C12: Open the needed Card sheet, select the student roll if applicable, then print/export. Cards are set to A4, Portrait, Fit to 1 page wide x 1 page tall, gridlines off.
A13: 9 | B13: Cells not to edit | C13: Do not edit formula/output cells, protected areas, report-card calculated fields, hidden helper rows, Dashboard formulas, or audit sheets unless you are an admin.
A14: 10 | B14: Avoid formula damage | C14: Use blue cells for entry. If a formula cell is accidentally changed, restore it from a backup copy of the workbook. Keep protection enabled where possible.
A15: 11 | B15: Compatibility notes | C15: Workbook is designed for Excel Desktop/Online, Google Sheets, WPS, LibreOffice, OnlyOffice, and mobile apps where possible. Avoid adding macros, XLOOKUP, FILTER, SORT, UNIQUE, LET, LAMBDA, or external links.
... A17: 13 | B17: MTR competency tracking | C17: Use MTR প্রথম..পঞ্চম sheets: mark হ্যাঁ/না per student for Bangla/Math/English competency. MTR Summary auto-rolls totals and builds the official কালাই, জয়পুরহাট submission block.
A18: Quick meaning of colors
A19: Blue/light-blue cells | B19: Editable input cells | C19: Teachers/admin staff can enter data here.
A20: Gray/light-gray cells | B20: Formula/output cells | C20: Do not edit unless you are repairing formulas.
A21: Red/Fail text | B21: Needs attention | C21: Fail status or issue is shown by text and color, not color alone.
A22: Final production note | B22: Report card inactive subject rows | C22: If a subject full mark is blank or 0 in Settings, it will not print as a subject row on the card and will not affect totals or GPA.
A23: Final production note | B23: Before publishing | C23: Check QC Flag, preview PDF, and verify a sample student from each class before final distribution.
A24: Final production note
A25: Student Name | B25: Required | C25: Enter on the correct class sheet.
A26: Student ID/Roll | B26: Required | C26: Use a unique roll number per class.
A27: Class | B27: Required | C27: Use the correct class sheet and/or dropdown in Report Card Hub.
A28: Section | B28: Recommended | C28: Use Settings default or class sheet input where available.
A29: Exam Name | B29: Required | C29: Enter in Settings.
A30: Academic Year | B30: Required | C30: Enter in Settings.
A31: Subject Names | B31: Required | C31: Controlled in Settings; avoid renaming subject headers directly in class sheets.
A32: Full Marks | B32: Required | C32: Enter in Settings for each class/subject. Blank or zero full mark means inactive subject.
A33: Pass Marks / Pass % | B33: Required | C33: Enter in Settings. Used for subject and final pass/fail logic.
A34: Obtained Marks | B34: Required for active subjects | C34: Enter in class sheets only.
A35: Attendance | B35: Optional/required by school | C35: Enter attendance percentage in class sheets.
A36: Publication Date | B36: Required before printing | C36: Enter in Settings; it appears on report cards.
A60: Final QA Notes | B60: Use this file after checking Settings, class sheets, and card preview.
A61: Editable cells | B61: Blue cells are editable. Formula/result cells are protected and should not be edited.
A62: Subject policy | B62: Class 1-2 use Drawing. Class 3-5 use Primary Science. Blank/zero full marks make a subject inactive.
A63: Pass/Fail policy | B63: If any active compulsory subject is below pass mark, Final Result is Fail. Missing active marks show Incomplete.
A64: Printing | B64: Open one Card sheet per class, select roll, preview as A4 Portrait, then export/print PDF.
A65: Compatibility | B65: No macros, VBA, external links, Power Query, or dynamic-array formulas are used.

Sheet Dashboard
A1: ULTIMATE SCHOOL RESULT COMMAND CENTER
A2: Convent-inspired premium theme • clean status widgets • cross-platform safe
A4: শ্রেণি | B4: মোট শিক্ষার্থী | C4: বিষয় | D4: Class Avg % | E4: Passed | F4: Pass % | G4: Top Avg | H4: A+ Count | I4: Needs Care | J4: Status | K4: Completed | L4: Incomplete | M4: Pass % Completed
A5: প্রথম | B5: =IFERROR(COUNTA(প্রথম!$D$6:$D$45),0) -> 35 | C5: =IFERROR(COUNTIF(প্রথম!$G$4:$N$4,">0"),0) -> 3 | D5: =IFERROR(IF(B5=0,0,IF(COUNT(প্রথম!$P$6:$P$45)=0,0,ROUND(AVERAGE(প্রথম!$P$6:$P$45),2))),0) -> 71.11 | E5: =IFERROR(COUNTIF(প্রথম!$S$6:$S$45,"Passed"),0) -> 28 | F5: =IFERROR(IF(B5=0,0,ROUND(E5/B5*100,2)),0) -> 80 | G5: =IFERROR(IF(B5=0,0,IF(COUNT(প্রথম!$P$6:$P$45)=0,0,MAX(প্রথম!$P$6:$P$45))),0) -> 99.33 | H5: =IFERROR(COUNTIF(প্রথম!$R$6:$R$45,"A+"),0) -> 16 | I5: =IFERROR(COUNTIF(প্রথম!$S$6:$S$45,"Needs Improvement"),0) -> 0 | J5: =IFERROR(IF(K5=0,"No completed marks",IF(M5>=90,"Excellent",IF(M5>=75,"Good","Review Needed"))),"Review Needed") -> Excellent | K5: =IFERROR(COUNTIF(প্রথম!$S$6:$S$45,"Passed")+COUNTIF(প্রথম!$S$6:$S$45,"Fail"),0) -> 31 | L5: =IFERROR(MAX(0,B5-K5),0) -> 4 | M5: =IFERROR(IF(K5=0,0,ROUND(E5/K5*100,2)),0) -> 90.32
A6: দ্বিতীয় | B6: =IFERROR(COUNTA(দ্বিতীয়!$D$6:$D$45),0) -> 22 | C6: =IFERROR(COUNTIF(দ্বিতীয়!$G$4:$N$4,">0"),0) -> 3 | D6: =IFERROR(IF(B6=0,0,IF(COUNT(দ্বিতীয়!$P$6:$P$45)=0,0,ROUND(AVERAGE(দ্বিতীয়!$P$6:$P$45),2))),0) -> 59.53 | E6: =IFERROR(COUNTIF(দ্বিতীয়!$S$6:$S$45,"Passed"),0) -> 16 | F6: =IFERROR(IF(B6=0,0,ROUND(E6/B6*100,2)),0) -> 72.73 | G6: =IFERROR(IF(B6=0,0,IF(COUNT(দ্বিতীয়!$P$6:$P$45)=0,0,MAX(দ্বিতীয়!$P$6:$P$45))),0) -> 87.33 | H6: =IFERROR(COUNTIF(দ্বিতীয়!$R$6:$R$45,"A+"),0) -> 3 | I6: =IFERROR(COUNTIF(দ্বিতীয়!$S$6:$S$45,"Needs Improvement"),0) -> 0 | J6: =IFERROR(IF(K6=0,"No completed marks",IF(M6>=90,"Excellent",IF(M6>=75,"Good","Review Needed"))),"Review Needed") -> Review Needed | K6: =IFERROR(COUNTIF(দ্বিতীয়!$S$6:$S$45,"Passed")+COUNTIF(দ্বিতীয়!$S$6:$S$45,"Fail"),0) -> 22 | L6: =IFERROR(MAX(0,B6-K6),0) -> 0 | M6: =IFERROR(IF(K6=0,0,ROUND(E6/K6*100,2)),0) -> 72.73
A7: তৃতীয় | B7: =IFERROR(COUNTA(তৃতীয়!$D$6:$D$45),0) -> 20 | C7: =IFERROR(COUNTIF(তৃতীয়!$G$4:$N$4,">0"),0) -> 6 | D7: =IFERROR(IF(B7=0,0,IF(COUNT(তৃতীয়!$P$6:$P$45)=0,0,ROUND(AVERAGE(তৃতীয়!$P$6:$P$45),2))),0) -> 40.82 | E7: =IFERROR(COUNTIF(তৃতীয়!$S$6:$S$45,"Passed"),0) -> 6 | F7: =IFERROR(IF(B7=0,0,ROUND(E7/B7*100,2)),0) -> 30 | G7: =IFERROR(IF(B7=0,0,IF(COUNT(তৃতীয়!$P$6:$P$45)=0,0,MAX(তৃতীয়!$P$6:$P$45))),0) -> 67.62 | H7: =IFERROR(COUNTIF(তৃতীয়!$R$6:$R$45,"A+"),0) -> 0 | I7: =IFERROR(COUNTIF(তৃতীয়!$S$6:$S$45,"Needs Improvement"),0) -> 0 | J7: =IFERROR(IF(K7=0,"No completed marks",IF(M7>=90,"Excellent",IF(M7>=75,"Good","Review Needed"))),"Review Needed") -> Review Needed | K7: =IFERROR(COUNTIF(তৃতীয়!$S$6:$S$45,"Passed")+COUNTIF(তৃতীয়!$S$6:$S$45,"Fail"),0) -> 19 | L7: =IFERROR(MAX(0,B7-K7),0) -> 1 | M7: =IFERROR(IF(K7=0,0,ROUND(E7/K7*100,2)),0) -> 31.58
A8: চতুর্থ | B8: =IFERROR(COUNTA(চতুর্থ!$D$6:$D$45),0) -> 17 | C8: =IFERROR(COUNTIF(চতুর্থ!$G$4:$N$4,">0"),0) -> 6 | D8: =IFERROR(IF(B8=0,0,IF(COUNT(চতুর্থ!$P$6:$P$45)=0,0,ROUND(AVERAGE(চতুর্থ!$P$6:$P$45),2))),0) -> 38.14 | E8: =IFERROR(COUNTIF(চতুর্থ!$S$6:$S$45,"Passed"),0) -> 3 | F8: =IFERROR(IF(B8=0,0,ROUND(E8/B8*100,2)),0) -> 17.65 | G8: =IFERROR(IF(B8=0,0,IF(COUNT(চতুর্থ!$P$6:$P$45)=0,0,MAX(চতুর্থ!$P$6:$P$45))),0) -> 63.33 | H8: =IFERROR(COUNTIF(চতুর্থ!$R$6:$R$45,"A+"),0) -> 0 | I8: =IFERROR(COUNTIF(চতুর্থ!$S$6:$S$45,"Needs Improvement"),0) -> 0 | J8: =IFERROR(IF(K8=0,"No completed marks",IF(M8>=90,"Excellent",IF(M8>=75,"Good","Review Needed"))),"Review Needed") -> Review Needed | K8: =IFERROR(COUNTIF(চতুর্থ!$S$6:$S$45,"Passed")+COUNTIF(চতুর্থ!$S$6:$S$45,"Fail"),0) -> 15 | L8: =IFERROR(MAX(0,B8-K8),0) -> 2 | M8: =IFERROR(IF(K8=0,0,ROUND(E8/K8*100,2)),0) -> 20
A9: পঞ্চম | B9: =IFERROR(COUNTA(পঞ্চম!$D$6:$D$45),0) -> 12 | C9: =IFERROR(COUNTIF(পঞ্চম!$G$4:$N$4,">0"),0) -> 6 | D9: =IFERROR(IF(B9=0,0,IF(COUNT(পঞ্চম!$P$6:$P$45)=0,0,ROUND(AVERAGE(পঞ্চম!$P$6:$P$45),2))),0) -> 54.43 | E9: =IFERROR(COUNTIF(পঞ্চম!$S$6:$S$45,"Passed"),0) -> 4 | F9: =IFERROR(IF(B9=0,0,ROUND(E9/B9*100,2)),0) -> 33.33 | G9: =IFERROR(IF(B9=0,0,IF(COUNT(পঞ্চম!$P$6:$P$45)=0,0,MAX(পঞ্চম!$P$6:$P$45))),0) -> 69.76 | H9: =IFERROR(COUNTIF(পঞ্চম!$R$6:$R$45,"A+"),0) -> 0 | I9: =IFERROR(COUNTIF(পঞ্চম!$S$6:$S$45,"Needs Improvement"),0) -> 0 | J9: =IFERROR(IF(K9=0,"No completed marks",IF(M9>=90,"Excellent",IF(M9>=75,"Good","Review Needed"))),"Review Needed") -> Review Needed | K9: =IFERROR(COUNTIF(পঞ্চম!$S$6:$S$45,"Passed")+COUNTIF(পঞ্চম!$S$6:$S$45,"Fail"),0) -> 11 | L9: =IFERROR(MAX(0,B9-K9),0) -> 1 | M9: =IFERROR(IF(K9=0,0,ROUND(E9/K9*100,2)),0) -> 36.36
A12: LIVE KPI WIDGETS / সারসংক্ষেপ
A13: Unique edge: offline-safe report card, result hub, dashboard, grade policy, QA certificate, competitor benchmark, print-safe design system. | J13: Release Gate: Platform-Safe / No Macro / Offline Ready
A15: =IFERROR(SUM(B5:B9),0) -> 106 | C15: =IFERROR(IF(SUM(B5:B9)=0,0,ROUND(SUMPRODUCT(D5:D9,B5:B9)/SUM(B5:B9),2)),0) -> 55.82 | E15: =IFERROR(IF(SUM(B5:B9)=0,0,ROUND(SUM(E5:E9)/SUM(B5:B9)*100,2)),0) -> 53.77 | G15: =IFERROR(SUM(H5:H9),0) -> 19

Sheet Executive Summary
A1: =IFERROR(Settings!$B$5,"") -> বেজখন্ড সঃ প্রাঃ বিদ্যালয়
A2: নির্বাহী সারসংক্ষেপ (Executive Summary) — বিদ্যালয় পরিদর্শন প্রতিবেদন
A3: =IFERROR("প্রস্তুতকারী তারিখ: "&TEXT(TODAY(),"DD-MM-YYYY"),"") -> প্রস্তুতকারী তারিখ: 11-07-2026
A5: মোট শিক্ষার্থী | D5: গড় ফলাফল % | G5: পাস % | J5: A+ সংখ্যা
A6: =IFERROR(Dashboard!A15,"") -> 106 | D6: =IFERROR(ROUND(Dashboard!C15,1),"") -> 55.8 | G6: =IFERROR(ROUND(Dashboard!E15,1),"") -> 53.8 | J6: =IFERROR(Dashboard!G15,"") -> 19
A9: শ্রেণিভিত্তিক ফলাফল
A10: শ্রেণি | D10: মোট শিক্ষার্থী | G10: গড় % | J10: পাস % | L10: অবস্থা
A11: =Dashboard!A5 -> প্রথম | D11: =Dashboard!B5 -> 35 | G11: =ROUND(Dashboard!D5,1) -> 71.1 | J11: =ROUND(Dashboard!F5,1) -> 80 | L11: =Dashboard!J5 -> Excellent
A12: =Dashboard!A6 -> দ্বিতীয় | D12: =Dashboard!B6 -> 22 | G12: =ROUND(Dashboard!D6,1) -> 59.5 | J12: =ROUND(Dashboard!F6,1) -> 72.7 | L12: =Dashboard!J6 -> Review Needed
A13: =Dashboard!A7 -> তৃতীয় | D13: =Dashboard!B7 -> 20 | G13: =ROUND(Dashboard!D7,1) -> 40.8 | J13: =ROUND(Dashboard!F7,1) -> 30 | L13: =Dashboard!J7 -> Review Needed
A14: =Dashboard!A8 -> চতুর্থ | D14: =Dashboard!B8 -> 17 | G14: =ROUND(Dashboard!D8,1) -> 38.1 | J14: =ROUND(Dashboard!F8,1) -> 17.7 | L14: =Dashboard!J8 -> Review Needed
A15: =Dashboard!A9 -> পঞ্চম | D15: =Dashboard!B9 -> 12 | G15: =ROUND(Dashboard!D9,1) -> 54.4 | J15: =ROUND(Dashboard!F9,1) -> 33.3 | L15: =Dashboard!J9 -> Review Needed
A18: মিড টার্ম রিভিউ (MTR) — সরকারি জমা ফরম্যাট, কালাই জয়পুরহাট
B19: ৩য় শ্রেণি (বাংলা) | F19: ৪র্থ শ্রেণি (গণিত) | J19: ৫ম শ্রেণি (ইংরেজি)
B20: মোট | C20: সক্ষম | D20: অক্ষম | E20: হার % | F20: মোট | G20: সক্ষম | H20: অক্ষম | I20: হার % | J20: মোট | K20: সক্ষম | L20: অক্ষম | M20: হার %
B21: ='MTR Summary'!B17 -> 20 | C21: ='MTR Summary'!C17 -> 0 | D21: ='MTR Summary'!D17 -> 0 | E21: ='MTR Summary'!E17 -> 0 | F21: ='MTR Summary'!F17 -> 17 | G21: ='MTR Summary'!G17 -> 0 | H21: ='MTR Summary'!H17 -> 0 | I21: ='MTR Summary'!I17 -> 0 | ... M21: ='MTR Summary'!M17 -> 0
J24: প্রধান শিক্ষকের স্বাক্ষর ও সীল

Sheet Report Card Hub
A1: ◆ Premium Report Card Hub
A2: Select class and roll. Open the matching Card sheet and print A4. | C2: Widget | D2: Purpose
C3: Class + Roll Selector | D3: Select class/roll, then open matching Card sheet for print.
A4: Select Class / শ্রেণি | B4: প্রথম | C4: Premium Print Mode | D4: All card sheets are A4 portrait, one-page print-ready.
A5: Select Roll / রোল | B5: 1 | C5: Safety Mode | D5: Formula cells locked; input cells editable.
A6: Matching Print Sheet | B6: =IFERROR(CONCATENATE("Card ",B4),"") -> Card প্রথম | C6: Compatibility Mode | D6: No macros, no scripts, no external links.
A7: Note: Change B4 (Roll) to 1–40 to load any student. Open the matching Card sheet to print.
A8: Release Gate Status | B8: Fixed: print areas, protection, dashboard metrics, and user-facing sheet package applied
A10: MTR Tracking: Enter per-student competency in MTR প্রথম–পঞ্চম sheets. See "MTR Summary" for rollups + official submission format.

Sheet Student Search
A1: =IFERROR(Settings!$B$5,"") -> বেজখন্ড সঃ প্রাঃ বিদ্যালয়
A2: শিক্ষার্থী অনুসন্ধান | যেকোনো শ্রেণির যেকোনো শিক্ষার্থীর সম্পূর্ণ প্রোফাইল (একাডেমিক + MTR)
P3: শ্রেণি | Q3: রোল | R3: নাম | S3: লেবেল
A4: শিক্ষার্থী নির্বাচন করুন: | P4: প্রথম | Q4: =IFERROR(IF(প্রথম!B6="","",প্রথম!B6),"") -> 1 | R4: =IFERROR(IF(প্রথম!D6="","",প্রথম!D6),"") -> মেঘনা | S4: =IF($R4="","",$P4&" - "&$R4&" (Roll "&$Q4&")") -> প্রথম - মেঘনা (Roll 1)
P5: প্রথম | Q5: =IFERROR(IF(প্রথম!B7="","",প্রথম!B7),"") -> 2 | R5: =IFERROR(IF(প্রথম!D7="","",প্রথম!D7),"") -> রওজা | S5: =IF($R5="","",$P5&" - "&$R5&" (Roll "&$Q5&")") -> প্রথম - রওজা (Roll 2)
A6: শ্রেণি | B6: =IFERROR(IF($B$4="","",INDEX($P$4:$P$203,MATCH($B$4,$S$4:$S$203,0))),"") | C6: রোল | D6: =IFERROR(IF($B$4="","",INDEX($Q$4:$Q$203,MATCH($B$4,$S$4:$S$203,0))),"") | P6: প্রথম | Q6: =IFERROR(IF(প্রথম!B8="","",প্রথম!B8),"") -> 3 | R6: =IFERROR(IF(প্রথম!D8="","",প্রথম!D8),"") -> রামিশা | S6: =IF($R6="","",$P6&" - "&$R6&" (Roll "&$Q6&")") -> প্রথম - রামিশা (Roll 3)
A7: নাম | B7: =IFERROR(IF($B$4="","",VLOOKUP($D$6,INDIRECT("'"&$B$6&"'!$B$6:$V$45"),3,FALSE())),"") | P7: প্রথম | Q7: =IFERROR(IF(প্রথম!B9="","",প্রথম!B9),"") -> 4 | R7: =IFERROR(IF(প্রথম!D9="","",প্রথম!D9),"") -> ইবতিহাজ | S7: =IF($R7="","",$P7&" - "&$R7&" (Roll "&$Q7&")") -> প্রথম - ইবতিহাজ (Roll 4)
A8: অভিভাবক | B8: =IFERROR(IF($B$4="","",VLOOKUP($D$6,INDIRECT("'"&$B$6&"'!$B$6:$V$45"),4,FALSE())),"") | C8: গ্রাম | D8: =IFERROR(IF($B$4="","",VLOOKUP($D$6,INDIRECT("'"&$B$6&"'!$B$6:$V$45"),5,FALSE())),"") | P8: প্রথম | Q8: =IFERROR(IF(প্রথম!B10="","",প্রথম!B10),"") -> 5 | R8: =IFERROR(IF(প্রথম!D10="","",প্রথম!D10),"") -> ফাহিম আব্দুল্লাহ | S8: =IF($R8="","",$P8&" - "&$R8&" (Roll "&$Q8&")") -> প্রথম - ফাহিম আব্দুল্লাহ (Roll 5)
P9: প্রথম | Q9: =IFERROR(IF(প্রথম!B11="","",প্রথম!B11),"") -> 6 | R9: =IFERROR(IF(প্রথম!D11="","",প্রথম!D11),"") -> রেজুওয়ান | S9: =IF($R9="","",$P9&" - "&$R9&" (Roll "&$Q9&")") -> প্রথম - রেজুওয়ান (Roll 6)
A10: বিষয়ভিত্তিক ফলাফল | P10: প্রথম | Q10: =IFERROR(IF(প্রথম!B12="","",প্রথম!B12),"") -> 7 | R10: =IFERROR(IF(প্রথম!D12="","",প্রথম!D12),"") -> ফাতেমা | S10: =IF($R10="","",$P10&" - "&$R10&" (Roll "&$Q10&")") -> প্রথম - ফাতেমা (Roll 7)
A11: বিষয় | B11: প্রাপ্ত নম্বর | P11: প্রথম | Q11: =IFERROR(IF(প্রথম!B13="","",প্রথম!B13),"") -> 8 | R11: =IFERROR(IF(প্রথম!D13="","",প্রথম!D13),"") -> এশা মুনি | S11: =IF($R11="","",$P11&" - "&$R11&" (Roll "&$Q11&")") -> প্রথম - এশা মুনি (Roll 8)
A12: =IFERROR(IF($B$4="","",INDIRECT("'"&$B$6&"'!$G$5")),"") | B12: =IFERROR(IF($B$4="","",IF(INDIRECT("'"&$B$6&"'!$G$5")="","",VLOOKUP($D$6,INDIRECT("'"&$B$6&"'!$B$6:$V$45"),6,FALSE()))),"") | P12: প্রথম | Q12: =IFERROR(IF(প্রথম!B14="","",প্রথম!B14),"") -> 9 | R12: =IFERROR(IF(প্রথম!D14="","",প্রথম!D14),"") -> তাবাসসুম | S12: =IF($R12="","",$P12&" - "&$R12&" (Roll "&$Q12&")") -> প্রথম - তাবাসসুম (Roll 9)
A13: =IFERROR(IF($B$4="","",INDIRECT("'"&$B$6&"'!$H$5")),"") | B13: =IFERROR(IF($B$4="","",IF(INDIRECT("'"&$B$6&"'!$H$5")="","",VLOOKUP($D$6,INDIRECT("'"&$B$6&"'!$B$6:$V$45"),7,FALSE()))),"") | P13: প্রথম | Q13: =IFERROR(IF(প্রথম!B15="","",প্রথম!B15),"") -> 10 | R13: =IFERROR(IF(প্রথম!D15="","",প্রথম!D15),"") -> তানভীর | S13: =IF($R13="","",$P13&" - "&$R13&" (Roll "&$Q13&")") -> প্রথম - তানভীর (Roll 10)
A14: =IFERROR(IF($B$4="","",INDIRECT("'"&$B$6&"'!$I$5")),"") | B14: =IFERROR(IF($B$4="","",IF(INDIRECT("'"&$B$6&"'!$I$5")="","",VLOOKUP($D$6,INDIRECT("'"&$B$6&"'!$B$6:$V$45"),8,FALSE()))),"") | P14: প্রথম | Q14: =IFERROR(IF(প্রথম!B16="","",প্রথম!B16),"") -> 11 | R14: =IFERROR(IF(প্রথম!D16="","",প্রথম!D16),"") -> জুনায়েদ | S14: =IF($R14="","",$P14&" - "&$R14&" (Roll "&$Q14&")") -> প্রথম - জুনায়েদ (Roll 11)
A15: =IFERROR(IF($B$4="","",INDIRECT("'"&$B$6&"'!$J$5")),"") | B15: =IFERROR(IF($B$4="","",IF(INDIRECT("'"&$B$6&"'!$J$5")="","",VLOOKUP($D$6,INDIRECT("'"&$B$6&"'!$B$6:$V$45"),9,FALSE()))),"") | P15: প্রথম | Q15: =IFERROR(IF(প্রথম!B17="","",প্রথম!B17),"") -> 12 | R15: =IFERROR(IF(প্রথম!D17="","",প্রথম!D17),"") -> আব্দুল্লাহ মুরাদ | S15: =IF($R15="","",$P15&" - "&$R15&" (Roll "&$Q15&")") -> প্রথম - আব্দুল্লাহ মুরাদ (Roll 12)
A16: =IFERROR(IF($B$4="","",INDIRECT("'"&$B$6&"'!$K$5")),"") | B16: =IFERROR(IF($B$4="","",IF(INDIRECT("'"&$B$6&"'!$K$5")="","",VLOOKUP($D$6,INDIRECT("'"&$B$6&"'!$B$6:$V$45"),10,FALSE()))),"") | P16: প্রথম | Q16: =IFERROR(IF(প্রথম!B18="","",প্রথম!B18),"") -> 13 | R16: =IFERROR(IF(প্রথম!D18="","",প্রথম!D18),"") -> আয়মান | S16: =IF($R16="","",$P16&" - "&$R16&" (Roll "&$Q16&")") -> প্রথম - আয়মান (Roll 13)
A17: =IFERROR(IF($B$4="","",INDIRECT("'"&$B$6&"'!$L$5")),"") | B17: =IFERROR(IF($B$4="","",IF(INDIRECT("'"&$B$6&"'!$L$5")="","",VLOOKUP($D$6,INDIRECT("'"&$B$6&"'!$B$6:$V$45"),11,FALSE()))),"") | P17: প্রথম | Q17: =IFERROR(IF(প্রথম!B19="","",প্রথম!B19),"") -> 14 | R17: =IFERROR(IF(প্রথম!D19="","",প্রথম!D19),"") -> আল হাবিব | S17: =IF($R17="","",$P17&" - "&$R17&" (Roll "&$Q17&")") -> প্রথম - আল হাবিব (Roll 14)
A18: =IFERROR(IF($B$4="","",INDIRECT("'"&$B$6&"'!$M$5")),"") | B18: =IFERROR(IF($B$4="","",IF(INDIRECT("'"&$B$6&"'!$M$5")="","",VLOOKUP($D$6,INDIRECT("'"&$B$6&"'!$B$6:$V$45"),12,FALSE()))),"") | P18: প্রথম | Q18: =IFERROR(IF(প্রথম!B20="","",প্রথম!B20),"") -> 15 | R18: =IFERROR(IF(প্রথম!D20="","",প্রথম!D20),"") -> আলিফ | S18: =IF($R18="","",$P18&" - "&$R18&" (Roll "&$Q18&")") -> প্রথম - আলিফ (Roll 15)
A19: =IFERROR(IF($B$4="","",INDIRECT("'"&$B$6&"'!$N$5")),"") | B19: =IFERROR(IF($B$4="","",IF(INDIRECT("'"&$B$6&"'!$N$5")="","",VLOOKUP($D$6,INDIRECT("'"&$B$6&"'!$B$6:$V$45"),13,FALSE()))),"") | P19: প্রথম | Q19: =IFERROR(IF(প্রথম!B21="","",প্রথম!B21),"") -> 16 | R19: =IFERROR(IF(প্রথম!D21="","",প্রথম!D21),"") -> মাসুদ রানা | S19: =IF($R19="","",$P19&" - "&$R19&" (Roll "&$Q19&")") -> প্রথম - মাসুদ রানা (Roll 16)
P20: প্রথম | Q20: =IFERROR(IF(প্রথম!B22="","",প্রথম!B22),"") -> 17 | R20: =IFERROR(IF(প্রথম!D22="","",প্রথম!D22),"") -> শারমিন | S20: =IF($R20="","",$P20&" - "&$R20&" (Roll "&$Q20&")") -> প্রথম - শারমিন (Roll 17)
A21: সার্বিক ফলাফল | P21: প্রথম | Q21: =IFERROR(IF(প্রথম!B23="","",প্রথম!B23),"") -> 18 | R21: =IFERROR(IF(প্রথম!D23="","",প্রথম!D23),"") -> রিয়া | S21: =IF($R21="","",$P21&" - "&$R21&" (Roll "&$Q21&")") -> প্রথম - রিয়া (Roll 18)
A22: মোট | B22: =IFERROR(IF($B$4="","",VLOOKUP($D$6,INDIRECT("'"&$B$6&"'!$B$6:$V$45"),14,FALSE())),"") | P22: প্রথম | Q22: =IFERROR(IF(প্রথম!B24="","",প্রথম!B24),"") -> 19 | R22: =IFERROR(IF(প্রথম!D24="","",প্রথম!D24),"") -> তাসফিয়া | S22: =IF($R22="","",$P22&" - "&$R22&" (Roll "&$Q22&")") -> প্রথম - তাসফিয়া (Roll 19)
A23: গড় % | B23: =IFERROR(IF($B$4="","",VLOOKUP($D$6,INDIRECT("'"&$B$6&"'!$B$6:$V$45"),15,FALSE())),"") | P23: প্রথম | Q23: =IFERROR(IF(প্রথম!B25="","",প্রথম!B25),"") -> 20 | R23: =IFERROR(IF(প্রথম!D25="","",প্রথম!D25),"") -> মরিয়ম | S23: =IF($R23="","",$P23&" - "&$R23&" (Roll "&$Q23&")") -> প্রথম - মরিয়ম (Roll 20)
A24: GPA | B24: =IFERROR(IF($B$4="","",VLOOKUP($D$6,INDIRECT("'"&$B$6&"'!$B$6:$V$45"),16,FALSE())),"") | P24: প্রথম | Q24: =IFERROR(IF(প্রথম!B26="","",প্রথম!B26),"") -> 21 | R24: =IFERROR(IF(প্রথম!D26="","",প্রথম!D26),"") -> নবিউল্লাহ | S24: =IF($R24="","",$P24&" - "&$R24&" (Roll "&$Q24&")") -> প্রথম - নবিউল্লাহ (Roll 21)
A25: গ্রেড | B25: =IFERROR(IF($B$4="","",VLOOKUP($D$6,INDIRECT("'"&$B$6&"'!$B$6:$V$45"),17,FALSE())),"") | P25: প্রথম | Q25: =IFERROR(IF(প্রথম!B27="","",প্রথম!B27),"") -> 22 | R25: =IFERROR(IF(প্রথম!D27="","",প্রথম!D27),"") -> জুনায়েদ ২ | S25: =IF($R25="","",$P25&" - "&$R25&" (Roll "&$Q25&")") -> প্রথম - জুনায়েদ ২ (Roll 22)
A26: ফলাফল | B26: =IFERROR(IF($B$4="","",VLOOKUP($D$6,INDIRECT("'"&$B$6&"'!$B$6:$V$45"),18,FALSE())),"") | P26: প্রথম | Q26: =IFERROR(IF(প্রথম!B28="","",প্রথম!B28),"") -> 23 | R26: =IFERROR(IF(প্রথম!D28="","",প্রথম!D28),"") -> জিসান | S26: =IF($R26="","",$P26&" - "&$R26&" (Roll "&$Q26&")") -> প্রথম - জিসান (Roll 23)
A27: উপস্থিতি % | B27: =IFERROR(IF($B$4="","",VLOOKUP($D$6,INDIRECT("'"&$B$6&"'!$B$6:$V$45"),19,FALSE())),"") | P27: প্রথম | Q27: =IFERROR(IF(প্রথম!B29="","",প্রথম!B29),"") -> 24 | R27: =IFERROR(IF(প্রথম!D29="","",প্রথম!D29),"") -> শিহাব | S27: =IF($R27="","",$P27&" - "&$R27&" (Roll "&$Q27&")") -> প্রথম - শিহাব (Roll 24)
A28: মন্তব্য | B28: =IFERROR(IF($B$4="","",VLOOKUP($D$6,INDIRECT("'"&$B$6&"'!$B$6:$V$45"),20,FALSE())),"") | P28: প্রথম | Q28: =IFERROR(IF(প্রথম!B30="","",প্রথম!B30),"") -> 25 | R28: =IFERROR(IF(প্রথম!D30="","",প্রথম!D30),"") -> হাইবাতুল্লাহ | S28: =IF($R28="","",$P28&" - "&$R28&" (Roll "&$Q28&")") -> প্রথম - হাইবাতুল্লাহ (Roll 25)
P29: প্রথম | Q29: =IFERROR(IF(প্রথম!B31="","",প্রথম!B31),"") -> 26 | R29: =IFERROR(IF(প্রথম!D31="","",প্রথম!D31),"") -> রিমন | S29: =IF($R29="","",$P29&" - "&$R29&" (Roll "&$Q29&")") -> প্রথম - রিমন (Roll 26)
A30: MTR দক্ষতা যাচাই (Mid Term Review) | P30: প্রথম | Q30: =IFERROR(IF(প্রথম!B32="","",প্রথম!B32),"") -> 27 | R30: =IFERROR(IF(প্রথম!D32="","",প্রথম!D32),"") -> রবিউল | S30: =IF($R30="","",$P30&" - "&$R30&" (Roll "&$Q30&")") -> প্রথম - রবিউল (Roll 27)
A31: বাংলা সাবলীল পঠন | B31: =IFERROR(IF($B$4="","",IF(VLOOKUP($D$6,INDIRECT("'MTR "&$B$6&"'!$B$4:$G$43"),3,FALSE())=0,"যাচাই হয়নি",VLOOKUP($D$6,INDIRECT("'MTR "&$B$6&"'!$B$4:$G$43"),3,FALSE()))),"") | P31: প্রথম | Q31: =IFERROR(IF(প্রথম!B33="","",প্রথম!B33),"") -> 28 | R31: =IFERROR(IF(প্রথম!D33="","",প্রথম!D33),"") -> সাদিকুল্লাহ | S31: =IF($R31="","",$P31&" - "&$R31&" (Roll "&$Q31&")") -> প্রথম - সাদিকুল্লাহ (Roll 28)
A32: গণিত চার নিয়ম দক্ষতা | B32: =IFERROR(IF($B$4="","",IF(VLOOKUP($D$6,INDIRECT("'MTR "&$B$6&"'!$B$4:$G$43"),4,FALSE())=0,"যাচাই হয়নি",VLOOKUP($D$6,INDIRECT("'MTR "&$B$6&"'!$B$4:$G$43"),4,FALSE()))),"") | P32: প্রথম | Q32: =IFERROR(IF(প্রথম!B34="","",প্রথম!B34),"") -> 29 | R32: =IFERROR(IF(প্রথম!D34="","",প্রথম!D34),"") -> তামিম | S32: =IF($R32="","",$P32&" - "&$R32&" (Roll "&$Q32&")") -> প্রথম - তামিম (Roll 29)
A33: English সাবলীল পঠন | B33: =IFERROR(IF($B$4="","",IF(VLOOKUP($D$6,INDIRECT("'MTR "&$B$6&"'!$B$4:$G$43"),5,FALSE())=0,"যাচাই হয়নি",VLOOKUP($D$6,INDIRECT("'MTR "&$B$6&"'!$B$4:$G$43"),5,FALSE()))),"") | P33: প্রথম | Q33: =IFERROR(IF(প্রথম!B35="","",প্রথম!B35),"") -> 30 | R33: =IFERROR(IF(প্রথম!D35="","",প্রথম!D35),"") -> রিফাত | S33: =IF($R33="","",$P33&" - "&$R33&" (Roll "&$Q33&")") -> প্রথম - রিফাত (Roll 30)
A34: MTR মন্তব্য | B34: =IFERROR(IF($B$4="","",VLOOKUP($D$6,INDIRECT("'MTR "&$B$6&"'!$B$4:$G$43"),6,FALSE())),"") | P34: প্রথম | Q34: =IFERROR(IF(প্রথম!B36="","",প্রথম!B36),"") -> 31 | R34: =IFERROR(IF(প্রথম!D36="","",প্রথম!D36),"") -> মো. আলী | S34: =IF($R34="","",$P34&" - "&$R34&" (Roll "&$Q34&")") -> প্রথম - মো. আলী (Roll 31)
P35: প্রথম | Q35: =IFERROR(IF(প্রথম!B37="","",প্রথম!B37),"") -> 32 | R35: =IFERROR(IF(প্রথম!D37="","",প্রথম!D37),"") -> নোমান | S35: =IF($R35="","",$P35&" - "&$R35&" (Roll "&$Q35&")") -> প্রথম - নোমান (Roll 32)
P36: প্রথম | Q36: =IFERROR(IF(প্রথম!B38="","",প্রথম!B38),"") -> 33 | R36: =IFERROR(IF(প্রথম!D38="","",প্রথম!D38),"") -> জিহাদ | S36: =IF($R36="","",$P36&" - "&$R36&" (Roll "&$Q36&")") -> প্রথম - জিহাদ (Roll 33)
P37: প্রথম | Q37: =IFERROR(IF(প্রথম!B39="","",প্রথম!B39),"") -> 34 | R37: =IFERROR(IF(প্রথম!D39="","",প্রথম!D39),"") -> সিয়াম | S37: =IF($R37="","",$P37&" - "&$R37&" (Roll "&$Q37&")") -> প্রথম - সিয়াম (Roll 34)
P38: প্রথম | Q38: =IFERROR(IF(প্রথম!B40="","",প্রথম!B40),"") -> 35 | R38: =IFERROR(IF(প্রথম!D40="","",প্রথম!D40),"") -> জান্নাতি | S38: =IF($R38="","",$P38&" - "&$R38&" (Roll "&$Q38&")") -> প্রথম - জান্নাতি (Roll 35)
P39: প্রথম | Q39: =IFERROR(IF(প্রথম!B41="","",প্রথম!B41),"") -> 36 | R39: =IFERROR(IF(প্রথম!D41="","",প্রথম!D41),"") | S39: =IF($R39="","",$P39&" - "&$R39&" (Roll "&$Q39&")")
P40: প্রথম | Q40: =IFERROR(IF(প্রথম!B42="","",প্রথম!B42),"") -> 37 | R40: =IFERROR(IF(প্রথম!D42="","",প্রথম!D42),"") | S40: =IF($R40="","",$P40&" - "&$R40&" (Roll "&$Q40&")")
...

Sheet How to Use
A1: How to Use / ব্যবহার নির্দেশিকা
A2: Software-style workflow for school result processing
A4: Step | B4: Menu | C4: Instruction
A5: 01 | B5: Settings | C5: স্কুলের নাম, পরীক্ষার নাম, গ্রেডিং সিস্টেম, পাস মার্ক ও রিপোর্ট কার্ড অপশন সেট করুন।
A6: 02 | B6: Class Sheets | C6: প্রতিটি শ্রেণির শিটে শিক্ষার্থীর নাম/রোল আছে। নীল ঘরে নম্বর ও উপস্থিতি লিখুন।
A7: 03 | B7: Dashboard | C7: সব শ্রেণির মোট শিক্ষার্থী, পাস %, গড়, A+ সংখ্যা ও chart স্বয়ংক্রিয়ভাবে দেখুন।
